Traceback (most recent call last):
  File "/home/pfistsa4/local_python_3.7.9/lib/python3.7/site-packages/jupyter_cache/executors/utils.py", line 56, in single_nb_execution
    record_timing=False,
  File "/home/pfistsa4/local_python_3.7.9/lib/python3.7/site-packages/nbclient/client.py", line 1112, in execute
    return NotebookClient(nb=nb, resources=resources, km=km, **kwargs).execute()
  File "/home/pfistsa4/local_python_3.7.9/lib/python3.7/site-packages/nbclient/util.py", line 74, in wrapped
    return just_run(coro(*args, **kwargs))
  File "/home/pfistsa4/local_python_3.7.9/lib/python3.7/site-packages/nbclient/util.py", line 53, in just_run
    return loop.run_until_complete(coro)
  File "/usr/prog/Python/3.7.9-foss-2018a/lib/python3.7/asyncio/base_events.py", line 587, in run_until_complete
    return future.result()
  File "/home/pfistsa4/local_python_3.7.9/lib/python3.7/site-packages/nbclient/client.py", line 554, in async_execute
    cell, index, execution_count=self.code_cells_executed + 1
  File "/home/pfistsa4/local_python_3.7.9/lib/python3.7/site-packages/nbclient/client.py", line 857, in async_execute_cell
    self._check_raise_for_error(cell, exec_reply)
  File "/home/pfistsa4/local_python_3.7.9/lib/python3.7/site-packages/nbclient/client.py", line 760, in _check_raise_for_error
    raise CellExecutionError.from_cell_and_msg(cell, exec_reply_content)
nbclient.exceptions.CellExecutionError: An error occurred while executing the following cell:
------------------
board.push(chess.Move.from_uci('b1b6'))
display(displayBoard(board))
getTurn(board)
------------------

[0;31m---------------------------------------------------------------------------[0m
[0;31mAssertionError[0m                            Traceback (most recent call last)
[0;32m/tmp/ipykernel_13891/1010622590.py[0m in [0;36m<module>[0;34m[0m
[0;32m----> 1[0;31m [0mboard[0m[0;34m.[0m[0mpush[0m[0;34m([0m[0mchess[0m[0;34m.[0m[0mMove[0m[0;34m.[0m[0mfrom_uci[0m[0;34m([0m[0;34m'b1b6'[0m[0;34m)[0m[0;34m)[0m[0;34m[0m[0;34m[0m[0m
[0m[1;32m      2[0m [0mdisplay[0m[0;34m([0m[0mdisplayBoard[0m[0;34m([0m[0mboard[0m[0;34m)[0m[0;34m)[0m[0;34m[0m[0;34m[0m[0m
[1;32m      3[0m [0mgetTurn[0m[0;34m([0m[0mboard[0m[0;34m)[0m[0;34m[0m[0;34m[0m[0m

[0;32m~/local_python_3.7.9/lib/python3.7/site-packages/chess/__init__.py[0m in [0;36mpush[0;34m(self, move)[0m
[1;32m   2197[0m         [0mpromoted[0m [0;34m=[0m [0mbool[0m[0;34m([0m[0mself[0m[0;34m.[0m[0mpromoted[0m [0;34m&[0m [0mfrom_bb[0m[0;34m)[0m[0;34m[0m[0;34m[0m[0m
[1;32m   2198[0m         [0mpiece_type[0m [0;34m=[0m [0mself[0m[0;34m.[0m[0m_remove_piece_at[0m[0;34m([0m[0mmove[0m[0;34m.[0m[0mfrom_square[0m[0;34m)[0m[0;34m[0m[0;34m[0m[0m
[0;32m-> 2199[0;31m         [0;32massert[0m [0mpiece_type[0m [0;32mis[0m [0;32mnot[0m [0;32mNone[0m[0;34m,[0m [0;34mf"push() expects move to be pseudo-legal, but got {move} in {self.board_fen()}"[0m[0;34m[0m[0;34m[0m[0m
[0m[1;32m   2200[0m         [0mcapture_square[0m [0;34m=[0m [0mmove[0m[0;34m.[0m[0mto_square[0m[0;34m[0m[0;34m[0m[0m
[1;32m   2201[0m         [0mcaptured_piece_type[0m [0;34m=[0m [0mself[0m[0;34m.[0m[0mpiece_type_at[0m[0;34m([0m[0mcapture_square[0m[0;34m)[0m[0;34m[0m[0;34m[0m[0m

[0;31mAssertionError[0m: push() expects move to be pseudo-legal, but got b1b6 in 8/R7/3k4/8/8/8/8/2QK4
AssertionError: push() expects move to be pseudo-legal, but got b1b6 in 8/R7/3k4/8/8/8/8/2QK4

